Workbook

Sheet POWER PATHWAY V4
A1: Region | B1: Value | C1: Unit | D1: 2020 | E1: 2021 | F1: 2022 | G1: 2023 | H1: 2025 | I1: 2030 | J1: 2035 | K1: 2040 | L1: 2045 | M1: 2050
A2: Advanced Economies | B2: Power generation emissions | C2: MtCO2 | D2: ='IEA EDGAR Emissions'!Q3 -> 3670.1762 | E2: ='IEA EDGAR Emissions'!R3 -> 3867.0883 | F2: ='IEA EDGAR Emissions'!S3 -> 3774.159 | G2: ='IEA EDGAR Emissions'!T3 -> 3471.8132 | H2: =G2+(I2-G2)*(H$1-G$1)/(I$1-G$1) -> 2837.6437 | I2: ='IEA WEO NZE 2024 2030-2050'!D4 -> 1252.22 | J2: ='IEA WEO NZE 2024 2030-2050'!E4 -> 50.85 | K2: ='IEA WEO NZE 2024 2030-2050'!F4 -> 26.64 | L2: ='IEA WEO NZE 2024 2030-2050'!G4 -> 23.37 | M2: ='IEA WEO NZE 2024 2030-2050'!H4 -> 60.57
A3: Advanced Economies | B3: Power generation activity | C3: PWh | D3: ='IEA World Energy Balances 2025'!N4/3600 -> 11.729167 | E3: ='IEA World Energy Balances 2025'!O4/3600 -> 12.082777 | F3: ='IEA World Energy Balances 2025'!P4/3600 -> 12.052724 | G3: ='IEA World Energy Balances 2025'!Q4/3600 -> 11.872386 | H3: =G3+(I3-G3)*(H$1-G$1)/(I$1-G$1) -> 12.665977 | I3: ='IEA WEO NZE 2024 2030-2050'!D9/1000 -> 14.649955 | J3: ='IEA WEO NZE 2024 2030-2050'!E9/1000 -> 17.457849 | K3: ='IEA WEO NZE 2024 2030-2050'!F9/1000 -> 20.964358 | L3: ='IEA WEO NZE 2024 2030-2050'!G9/1000 -> 22.970578 | M3: ='IEA WEO NZE 2024 2030-2050'!H9/1000 -> 24.61261
A4: Advanced Economies | B4: Power generation emissions intensity | C4: kgCO2/MWh | D4: =D2/D3 -> 312.91023 | E4: =E2/E3 -> 320.04964 | F4: =F2/F3 -> 313.13743 | G4: =G2/G3 -> 292.42758 | H4: =H2/H3 -> 224.03669 | I4: =I2/I3 -> 85.47603 | J4: =J2/J3 -> 2.91273 | K4: =K2/K3 -> 1.2707281 | ... M4: =M2/M3 -> 2.4609336
A6: Emerging economies | B6: Power generation emissions | C6: MtCO2 | D6: ='IEA EDGAR Emissions'!Q4 -> 10029.257 | E6: ='IEA EDGAR Emissions'!R4 -> 10913.318 | F6: ='IEA EDGAR Emissions'!S4 -> 11183.501 | G6: ='IEA EDGAR Emissions'!T4 -> 11781.149 | H6: =G6+(I6-G6)*(H$1-G$1)/(I$1-G$1) -> 10573.315 | I6: ='IEA WEO NZE 2024 2030-2050'!D15 -> 7553.73 | J6: ='IEA WEO NZE 2024 2030-2050'!E15 -> 3166.39 | K6: ='IEA WEO NZE 2024 2030-2050'!F15 -> 660.95 | L6: ='IEA WEO NZE 2024 2030-2050'!G15 -> 159 | M6: ='IEA WEO NZE 2024 2030-2050'!H15 -> 70.75
A7: Emerging economies | B7: Power generation activity | C7: PWh | D7: ='IEA World Energy Balances 2025'!N5/3600 -> 19.587222 | E7: ='IEA World Energy Balances 2025'!O5/3600 -> 21.316926 | F7: ='IEA World Energy Balances 2025'!P5/3600 -> 22.15407 | G7: ='IEA World Energy Balances 2025'!Q5/3600 -> 23.315877 | H7: =G7+(I7-G7)*(H$1-G$1)/(I$1-G$1) -> 25.193572 | I7: ='IEA WEO NZE 2024 2030-2050'!D20/1000 -> 29.887809 | J7: ='IEA WEO NZE 2024 2030-2050'!E20/1000 -> 36.843797 | K7: ='IEA WEO NZE 2024 2030-2050'!F20/1000 -> 44.585216 | L7: ='IEA WEO NZE 2024 2030-2050'!G20/1000 -> 51.676311 | M7: ='IEA WEO NZE 2024 2030-2050'!H20/1000 -> 57.988024
A8: Emerging economies | B8: Power generation emissions intensity | C8: kgCO2/MWh | D8: =D6/D7 -> 512.03057 | E8: =E6/E7 -> 511.95555 | F8: =F6/F7 -> 504.80573 | G8: =G6/G7 -> 505.28438 | H8: =H6/H7 -> 419.68304 | I8: =I6/I7 -> 252.73616 | J8: =J6/J7 -> 85.940926 | K8: =K6/K7 -> 14.824421 | ... M8: =M6/M7 -> 1.2200795
A10: Global | B10: Power generation emissions | C10: MtCO2 | D10: ='IEA EDGAR Emissions'!Q5 -> 13699.433 | E10: ='IEA EDGAR Emissions'!R5 -> 14780.407 | F10: ='IEA EDGAR Emissions'!S5 -> 14957.66 | G10: ='IEA EDGAR Emissions'!T5 -> 15252.962 | H10: =G10+(I10-G10)*(H$1-G$1)/(I$1-G$1) -> 13410.958 | I10: ='IEA WEO NZE 2024 2030-2050'!D26 -> 8805.95 | J10: ='IEA WEO NZE 2024 2030-2050'!E26 -> 3217.24 | K10: ='IEA WEO NZE 2024 2030-2050'!F26 -> 687.59 | L10: ='IEA WEO NZE 2024 2030-2050'!G26 -> 182.37 | M10: ='IEA WEO NZE 2024 2030-2050'!H26 -> 131.32
A11: Global | B11: Power generation activity | C11: PWh | D11: ='IEA World Energy Balances 2025'!N6/3600 -> 31.316389 | E11: ='IEA World Energy Balances 2025'!O6/3600 -> 33.399702 | F11: ='IEA World Energy Balances 2025'!P6/3600 -> 34.206794 | G11: ='IEA World Energy Balances 2025'!Q6/3600 -> 35.188263 | H11: =G11+(I11-G11)*(H$1-G$1)/(I$1-G$1) -> 37.851085 | I11: ='IEA WEO NZE 2024 2030-2050'!D31/1000 -> 44.508139 | J11: ='IEA WEO NZE 2024 2030-2050'!E31/1000 -> 54.275284 | K11: ='IEA WEO NZE 2024 2030-2050'!F31/1000 -> 65.526532 | L11: ='IEA WEO NZE 2024 2030-2050'!G31/1000 -> 74.627417 | M11: ='IEA WEO NZE 2024 2030-2050'!H31/1000 -> 82.584634
A12: Global | B12: Power generation emissions intensity | C12: kgCO2/MWh | D12: =D10/D11 -> 437.4525 | E12: =E10/E11 -> 442.53109 | F12: =F10/F11 -> 437.27163 | G12: =G10/G11 -> 433.46731 | H12: =H10/H11 -> 354.30843 | I12: =I10/I11 -> 197.85033 | J12: =J10/J11 -> 59.276336 | K12: =K10/K11 -> 10.493307 | ... M12: =M10/M11 -> 1.5901263

Sheet IEA WEO NZE 2024 2030-2050
A1: Region | B1: Value | C1: Unit | D1: 2030 | E1: 2035 | F1: 2040 | G1: 2045 | H1: 2050 | K1: Heat loss factor from IEA world energy balances
A2: Advanced Economies | B2: Net power emissions | C2: MtCO2 | D2: 1276.59 | E2: -52.62 | F2: -129.79 | G2: -148.56 | H2: -115.68 | K2: AE | L2: 1.21
A3: Advanced Economies | B3: Biomass power emissions | C3: MtCO2 | D3: 24.37 | E3: -103.47 | F3: -156.43 | G3: -171.93 | H3: -176.25 | K3: EE | L3: 1.16
A4: Advanced Economies | B4: Gross power emissions | C4: MtCO2 | D4: =D2-D3 -> 1252.22 | E4: =E2-E3 -> 50.85 | F4: =F2-F3 -> 26.64 | G4: =G2-G3 -> 23.37 | H4: =H2-H3 -> 60.57 | K4: Global | L4: 1.16
A5: Advanced Economies | B5: Electricity activity | C5: TWh | D5: 13933.03 | E5: 16819.91 | F5: 20406.75 | G5: 22499.35 | H5: 24225.41
A6: Advanced Economies | B6: Heat activity | C6: PJ | D6: 2133 | E6: 1898 | F6: 1659 | G6: 1402 | H6: 1152
A7: Advanced Economies | B7: Heat consumption | C7: TWh | D7: =D6/3.6 -> 592.5 | E7: =E6/3.6 -> 527.22222 | F7: =F6/3.6 -> 460.83333 | G7: =G6/3.6 -> 389.44444 | H7: =H6/3.6 -> 320
A8: Advanced Economies | B8: Heat activity | C8: TWh | D8: =D7*$L$2 -> 716.925 | E8: =E7*$L$2 -> 637.93889 | F8: =F7*$L$2 -> 557.60833 | G8: =G7*$L$2 -> 471.22778 | H8: =H7*$L$2 -> 387.2
A9: Advanced Economies | B9: Power activity | C9: TWh | D9: =D8+D5 -> 14649.955 | E9: =E8+E5 -> 17457.849 | F9: =F8+F5 -> 20964.358 | G9: =G8+G5 -> 22970.578 | H9: =H8+H5 -> 24612.61
A10: Advanced Economies | B10: Emissions intensity | C10: kgCO2/MWh | D10: =(D4/D9)*1000 -> 85.47603 | E10: =(E4/E9)*1000 -> 2.91273 | F10: =(F4/F9)*1000 -> 1.2707281 | G10: =(G4/G9)*1000 -> 1.0173884 | H10: =(H4/H9)*1000 -> 2.4609336
A13: Emerging Economies | B13: Net power emissions | C13: MtCO2 | D13: =D24-D2 -> 7584.28 | E13: =E24-E2 -> 3106.96 | F13: =F24-F2 -> 513.75 | G13: =G24-G2 -> -52.82 | H13: =H24-H2 -> -183.32
A14: Emerging Economies | B14: Biomass power emissions | C14: MtCO2 | D14: =D25-D3 -> 30.55 | E14: =E25-E3 -> -59.43 | F14: =F25-F3 -> -147.2 | G14: =G25-G3 -> -211.82 | H14: =H25-H3 -> -254.07
A15: Emerging Economies | B15: Gross power emissions | C15: MtCO2 | D15: =D13-D14 -> 7553.73 | E15: =E13-E14 -> 3166.39 | F15: =F13-F14 -> 660.95 | G15: =G13-G14 -> 159 | H15: =H13-H14 -> 70.75
A16: Emerging Economies | B16: Electricity activity | C16: TWh | D16: =D27-D5 -> 25849.72 | E16: =E27-E5 -> 33264.23 | F16: =F27-F5 -> 41558.26 | G16: =G27-G5 -> 49206.8 | H16: =H27-H5 -> 55968.98
A17: Emerging Economies | B17: Heat activity | C17: PJ | D17: =(D28*1000)-D6 -> 12532 | E17: =(E28*1000)-E6 -> 11109 | F17: =(F28*1000)-F6 -> 9394 | G17: =(G28*1000)-G6 -> 7664 | H17: =(H28*1000)-H6 -> 6266
A18: Emerging Economies | B18: Heat consumption | C18: TWh | D18: =D17/3.6 -> 3481.1111 | E18: =E17/3.6 -> 3085.8333 | F18: =F17/3.6 -> 2609.4444 | G18: =G17/3.6 -> 2128.8889 | H18: =H17/3.6 -> 1740.5556
A19: Emerging Economies | B19: Heat activity | C19: TWh | D19: =D18*$L$3 -> 4038.0889 | E19: =E18*$L$3 -> 3579.5667 | F19: =F18*$L$3 -> 3026.9556 | G19: =G18*$L$3 -> 2469.5111 | H19: =H18*$L$3 -> 2019.0444
A20: Emerging Economies | B20: Power activity | C20: TWh | D20: =D16+D19 -> 29887.809 | E20: =E16+E19 -> 36843.797 | F20: =F16+F19 -> 44585.216 | G20: =G16+G19 -> 51676.311 | H20: =H16+H19 -> 57988.024
A21: Emerging Economies | B21: Emissions intensity | C21: kgCO2/MWh | D21: =(D15/D20)*1000 -> 252.73616 | E21: =(E15/E20)*1000 -> 85.940926 | F21: =(F15/F20)*1000 -> 14.824421 | G21: =(G15/G20)*1000 -> 3.076845 | H21: =(H15/H20)*1000 -> 1.2200795
A24: Global | B24: Net power emissions | C24: MtCO2 | D24: 8860.87 | E24: 3054.34 | F24: 383.96 | G24: -201.38 | H24: -299
A25: Global | B25: Biomass power emissions | C25: MtCO2 | D25: 54.92 | E25: -162.9 | F25: -303.63 | G25: -383.75 | H25: -430.32
A26: Global | B26: Gross power emissions | C26: MtCO2 | D26: =D24-D25 -> 8805.95 | E26: =E24-E25 -> 3217.24 | F26: =F24-F25 -> 687.59 | G26: =G24-G25 -> 182.37 | H26: =H24-H25 -> 131.32
A27: Global | B27: Electricity activity | C27: TWh | D27: 39782.75 | E27: 50084.14 | F27: 61965.01 | G27: 71706.15 | H27: 80194.39
A28: Global | B28: Heat activity | C28: EJ | D28: 14.665 | E28: 13.007 | F28: 11.053 | G28: 9.066 | H28: 7.418
A29: Global | B29: Heat consumption | C29: TWh | D29: =D28/0.0036 -> 4073.6111 | E29: =E28/0.0036 -> 3613.0556 | F29: =F28/0.0036 -> 3070.2778 | G29: =G28/0.0036 -> 2518.3333 | H29: =H28/0.0036 -> 2060.5556
A30: Global | B30: Heat activity | C30: TWh | D30: =D29*$L$4 -> 4725.3889 | E30: =E29*$L$4 -> 4191.1444 | F30: =F29*$L$4 -> 3561.5222 | G30: =G29*$L$4 -> 2921.2667 | H30: =H29*$L$4 -> 2390.2444
A31: Global | B31: Power activity | C31: TWh | D31: =D27+D30 -> 44508.139 | E31: =E27+E30 -> 54275.284 | F31: =F27+F30 -> 65526.532 | G31: =G27+G30 -> 74627.417 | H31: =H27+H30 -> 82584.634
A32: Global | B32: Emissions intensity | C32: kgCO2/MWh | D32: =(D26/D31)*1000 -> 197.85033 | E32: =(E26/E31)*1000 -> 59.276336 | F32: =(F26/F31)*1000 -> 10.493307 | G32: =(G26/G31)*1000 -> 2.44374 | H32: =(H26/H31)*1000 -> 1.5901263

Sheet IEA EDGAR Emissions
A1: IPCC_annex | B1: C_group_IM24_sh | C1: Country_code_A3 | D1: Name | E1: ipcc_code_2006_for_standard_report | F1: ipcc_code_2006_for_standard_report_name | G1: Substance | H1: fossil_bio | I1: Y_2020 | J1: Y_2021 | K1: Y_2022 | L1: Y_2023 | O1: 2020 Emissions
A2: Non-Annex_I | B2: Rest Central America | C2: ABW | D2: Aruba | E2: 1.A.1.a | F2: Main Activity Electricity and Heat Production | G2: CO2 | H2: fossil | I2: 251.29352 | J2: 256.13249 | K2: 271.01221 | L2: 270.46344 | O2: Geography | P2: Unit | Q2: 2020 | R2: 2021 | S2: 2022 | T2: 2023
A3: Non-Annex_I | B3: Rest Central America | C3: ABW | D3: Aruba | E3: 1.A.2 | F3: Manufacturing Industries and Construction | G3: CO2 | H3: fossil | I3: 28.657397 | J3: 34.630667 | K3: 36.642767 | L3: 36.56857 | O3: Advanced Economies | P3: MtCO2 | Q3: {=SUMPRODUCT(($E$2:$E$3534="1.A.1.a")*ISNUMBER(MATCH($C$2:$C$3534,{"AUS","AUT","BEL","CAN","CHL","COL","CRI","CZE","DNK","EST","FIN","FRA","DEU","GRC","HUN","ISL","IRL","ISR","ITA","JPN","KOR","LVA","LTU","LUX","MEX","NLD","NZL","NOR","POL","PRT","SVK","SVN","ESP","SWE","CHE","TUR","GBR","USA"},0))*$I$2:$I$3534) /1000} -> 3670.1762 | R3: {=SUMPRODUCT(($E$2:$E$3534="1.A.1.a")*ISNUMBER(MATCH($C$2:$C$3534,{"AUS","AUT","BEL","CAN","CHL","COL","CRI","CZE","DNK","EST","FIN","FRA","DEU","GRC","HUN","ISL","IRL","ISR","ITA","JPN","KOR","LVA","LTU","LUX","MEX","NLD","NZL","NOR","POL","PRT","SVK","SVN","ESP","SWE","CHE","TUR","GBR","USA"},0))*$J$2:$J$3534) /1000} -> 3867.0883 | S3: {=SUMPRODUCT(($E$2:$E$3534="1.A.1.a")*ISNUMBER(MATCH($C$2:$C$3534,{"AUS","AUT","BEL","CAN","CHL","COL","CRI","CZE","DNK","EST","FIN","FRA","DEU","GRC","HUN","ISL","IRL","ISR","ITA","JPN","KOR","LVA","LTU","LUX","MEX","NLD","NZL","NOR","POL","PRT","SVK","SVN","ESP","SWE","CHE","TUR","GBR","USA"},0))*$K$2:$K$3534) /1000} -> 3774.159 | T3: {=SUMPRODUCT(($E$2:$E$3534="1.A.1.a")*ISNUMBER(MATCH($C$2:$C$3534,{"AUS","AUT","BEL","CAN","CHL","COL","CRI","CZE","DNK","EST","FIN","FRA","DEU","GRC","HUN","ISL","IRL","ISR","ITA","JPN","KOR","LVA","LTU","LUX","MEX","NLD","NZL","NOR","POL","PRT","SVK","SVN","ESP","SWE","CHE","TUR","GBR","USA"},0))*$L$2:$L$3534) /1000} -> 3471.8132
A4: Non-Annex_I | B4: Rest Central America | C4: ABW | D4: Aruba | E4: 1.A.3.a | F4: Civil Aviation | G4: CO2 | H4: fossil | I4: 12.101409 | J4: 12.62712 | K4: 13.360779 | L4: 15.254929 | O4: Emerging Economies | P4: MtCO2 | Q4: =Q5-Q3 -> 10029.257 | R4: =R5-R3 -> 10913.318 | S4: =S5-S3 -> 11183.501 | T4: =T5-T3 -> 11781.149
A5: Non-Annex_I | B5: Rest Central America | C5: ABW | D5: Aruba | E5: 1.A.3.b_noRES | F5: Road Transportation no resuspension | G5: CO2 | H5: fossil | I5: 138.52495 | J5: 144.87296 | K5: 153.2906 | L5: 152.9802 | O5: Global | P5: MtCO2 | Q5: =SUMIFS($I$2:$I$3534,$E$2:$E$3534,"1.A.1.a")/1000 -> 13699.433 | R5: =SUMIFS($J$2:$J$3534,$E$2:$E$3534,"1.A.1.a")/1000 -> 14780.407 | S5: =SUMIFS($K$2:$K$3534,$E$2:$E$3534,"1.A.1.a")/1000 -> 14957.66 | T5: =SUMIFS($L$2:$L$3534,$E$2:$E$3534,"1.A.1.a")/1000 -> 15252.962
A6: Non-Annex_I | B6: Rest Central America | C6: ABW | D6: Aruba | E6: 1.A.3.d | F6: Water-borne Navigation | G6: CO2 | H6: fossil | I6: 10.644315 | J6: 10.828778 | K6: 11.458059 | L6: 12.209959
A7: Non-Annex_I | B7: Rest Central America | C7: ABW | D7: Aruba | E7: 1.A.3.e | F7: Other Transportation | G7: CO2 | H7: fossil | I7: 4.5708872 | J7: 4.3694703 | K7: 4.6234342 | L7: 4.6140723
A8: Non-Annex_I | B8: Rest Central America | C8: ABW | D8: Aruba | E8: 1.A.4 | F8: Residential and other sectors | G8: CO2 | H8: fossil | I8: 38.09707 | J8: 38.698683 | K8: 39.608363 | L8: 39.528161
A9: Non-Annex_I | B9: Rest Central America | C9: ABW | D9: Aruba | E9: 1.A.5 | F9: Non-Specified | G9: CO2 | H9: fossil | I9: 2.9238011 | J9: 3.2194985 | K9: 3.4065293 | L9: 3.3996315
A10: Non-Annex_I | B10: Rest Central America | C10: ABW | D10: Aruba | E10: 1.B.2 | F10: Oil and Natural Gas | G10: CO2 | H10: fossil
A11: Non-Annex_I | B11: Rest Central America | C11: ABW | D11: Aruba | E11: 2.A.3 | F11: Glass Production | G11: CO2 | H11: fossil | I11: 0.0052707 | J11: 0.0052921741 | K11: 0.0053137031 | L11: 0.0053347818
A12: Non-Annex_I | B12: Rest Central America | C12: ABW | D12: Aruba | E12: 2.A.4 | F12: Other Process Uses of Carbonates | G12: CO2 | H12: fossil | I12: 0.0001736 | J12: 0.00020568735 | K12: 0.00024372495 | L12: 0.00028964794
A13: Non-Annex_I | B13: Rest Central America | C13: ABW | D13: Aruba | E13: 2.D | F13: Non-Energy Products from Fuels and Solvent Use | G13: CO2 | H13: fossil | I13: 1.9161013 | J13: 1.9653543 | K13: 2.0567731 | L13: 2.0992591
A14: Non-Annex_I | B14: India + | C14: AFG | D14: Afghanistan | E14: 1.A.1.a | F14: Main Activity Electricity and Heat Production | G14: CO2 | H14: fossil | I14: 3097.5843 | J14: 3028.3871 | K14: 2743.0271 | L14: 2819.4205
A15: Non-Annex_I | B15: India + | C15: AFG | D15: Afghanistan | E15: 1.A.1.bc | F15: Petroleum Refining - Manufacture of Solid Fuels and Other Energy Industries | G15: CO2 | H15: fossil | I15: 370.57202
A16: Non-Annex_I | B16: India + | C16: AFG | D16: Afghanistan | E16: 1.A.2 | F16: Manufacturing Industries and Construction | G16: CO2 | H16: fossil | I16: 2756.0966 | J16: 3510.5019 | K16: 3225.386 | L16: 3463.4991
A17: Non-Annex_I | B17: India + | C17: AFG | D17: Afghanistan | E17: 1.A.3.a | F17: Civil Aviation | G17: CO2 | H17: fossil | I17: 219.34517 | J17: 227.7743 | K17: 203.13169 | L17: 270.52614
A18: Non-Annex_I | B18: India + | C18: AFG | D18: Afghanistan | E18: 1.A.3.b_noRES | F18: Road Transportation no resuspension | G18: CO2 | H18: fossil | I18: 3702.3051 | J18: 3740.3725 | K18: 3335.7066 | L18: 3319.9407
A19: Non-Annex_I | B19: India + | C19: AFG | D19: Afghanistan | E19: 1.A.3.c | F19: Railways | G19: CO2 | H19: fossil
A20: Non-Annex_I | B20: India + | C20: AFG | D20: Afghanistan | E20: 1.A.3.d | F20: Water-borne Navigation | G20: CO2 | H20: fossil | I20: 254.73213 | J20: 308.61015 | K20: 275.22204 | L20: 265.6358
A21: Non-Annex_I | B21: India + | C21: AFG | D21: Afghanistan | E21: 1.A.3.e | F21: Other Transportation | G21: CO2 | H21: fossil | I21: 267.16801 | J21: 263.49576 | K21: 234.98704 | L21: 233.8764
A22: Non-Annex_I | B22: India + | C22: AFG | D22: Afghanistan | E22: 1.A.4 | F22: Residential and other sectors | G22: CO2 | H22: fossil | I22: 1209.8082 | J22: 1172.145 | K22: 1045.3326 | L22: 1040.392
A23: Non-Annex_I | B23: India + | C23: AFG | D23: Afghanistan | E23: 1.A.5 | F23: Non-Specified | G23: CO2 | H23: fossil | I23: 55.712801 | J23: 59.382521 | K23: 52.957091 | L23: 52.706795
A24: Non-Annex_I | B24: India + | C24: AFG | D24: Afghanistan | E24: 1.B.1 | F24: Solid Fuels | G24: CO2 | H24: fossil | I24: 34.208507 | J24: 37.501426 | K24: 36.811691 | L24: 37.211192
A25: Non-Annex_I | B25: India + | C25: AFG | D25: Afghanistan | E25: 1.B.2 | F25: Oil and Natural Gas | G25: CO2 | H25: fossil | I25: 0.0056872 | J25: 1.6536382e-05 | K25: 1.3752504e-05 | L25: 6.5453638e-06
A26: Non-Annex_I | B26: India + | C26: AFG | D26: Afghanistan | E26: 2.A.1 | F26: Cement production | G26: CO2 | H26: fossil | I26: 28.225153 | J26: 14.112577 | K26: 9.1731748 | L26: 9.1628262
A27: Non-Annex_I | B27: India + | C27: AFG | D27: Afghanistan | E27: 2.A.3 | F27: Glass Production | G27: CO2 | H27: fossil | I27: 1.7427974 | J27: 1.9519783 | K27: 1.9519783 | L27: 1.9519783
A28: Non-Annex_I | B28: India + | C28: AFG | D28: Afghanistan | E28: 2.B | F28: Chemical Industry | G28: CO2 | H28: fossil
A29: Non-Annex_I | B29: India + | C29: AFG | D29: Afghanistan | E29: 2.C | F29: Metal Industry | G29: CO2 | H29: fossil
A30: Non-Annex_I | B30: India + | C30: AFG | D30: Afghanistan | E30: 2.D | F30: Non-Energy Products from Fuels and Solvent Use | G30: CO2 | H30: fossil | I30: 81.265879 | J30: 81.665558 | K30: 81.162568 | L30: 81.955777
A31: Non-Annex_I | B31: India + | C31: AFG | D31: Afghanistan | E31: 3.C.2 | F31: Liming | G31: CO2 | H31: fossil | I31: 6.4952381 | J31: 1.047619 | K31: 2.5142857 | L31: 1.76
A32: Non-Annex_I | B32: India + | C32: AFG | D32: Afghanistan | E32: 3.C.3 | F32: Urea application | G32: CO2 | H32: fossil | I32: 58.299989 | J32: 39.44285 | K32: 50.599991 | L32: 50.599991
A33: Non-Annex_I | B33: Southern_Africa | C33: AGO | D33: Angola | E33: 1.A.1.a | F33: Main Activity Electricity and Heat Production | G33: CO2 | H33: fossil | I33: 3559.029 | J33: 3599.2005 | K33: 3710.0271 | L33: 3727.3556
A34: Non-Annex_I | B34: Southern_Africa | C34: AGO | D34: Angola | E34: 1.A.1.bc | F34: Petroleum Refining - Manufacture of Solid Fuels and Other Energy Industries | G34: CO2 | H34: fossil | I34: 1224.7996 | J34: 967.66203 | K34: 895.81903 | L34: 817.22048
A35: Non-Annex_I | B35: Southern_Africa | C35: AGO | D35: Angola | E35: 1.A.2 | F35: Manufacturing Industries and Construction | G35: CO2 | H35: fossil | I35: 1061.1693 | J35: 1327.6925 | K35: 1730.8093 | L35: 1646.2979
A36: Non-Annex_I | B36: Southern_Africa | C36: AGO | D36: Angola | E36: 1.A.3.a | F36: Civil Aviation | G36: CO2 | H36: fossil | I36: 12.219722 | J36: 10.689114 | K36: 46.232572 | L36: 52.106165
A37: Non-Annex_I | B37: Southern_Africa | C37: AGO | D37: Angola | E37: 1.A.3.b_noRES | F37: Road Transportation no resuspension | G37: CO2 | H37: fossil | I37: 3870.8567 | J37: 7051.3758 | K37: 8220.7424 | L37: 8479.7924
A38: Non-Annex_I | B38: Southern_Africa | C38: AGO | D38: Angola | E38: 1.A.3.d | F38: Water-borne Navigation | G38: CO2 | H38: fossil | I38: 16.677983 | J38: 27.984747 | K38: 32.839416 | L38: 30.764549
A39: Non-Annex_I | B39: Southern_Africa | C39: AGO | D39: Angola | E39: 1.A.3.e | F39: Other Transportation | G39: CO2 | H39: fossil
A40: Non-Annex_I | B40: Southern_Africa | C40: AGO | D40: Angola | E40: 1.A.4 | F40: Residential and other sectors | G40: CO2 | H40: fossil | I40: 5344.2554 | J40: 7244.5449 | K40: 6915.3735 | L40: 7133.289
...

Sheet IEA World Energy Balances 2025
A1: Source: IEA (2025). All rights reserved. (https://www.iea.org/terms)
A2: Country | B2: Product | C2: Flow | D2: 2020 | E2: 2021 | F2: 2022 | G2: 2023 | L2: 2020 Activity
A3: Australia | B3: Coal, peat and oil shale | C3: Production (PJ) | D3: 12335 | E3: 11467.57 | F3: 11416.066 | G3: 10814.978 | L3: Geography | M3: Unit | N3: 2020 | O3: 2021 | P3: 2022 | Q3: 2023
A4: Australia | B4: Coal, peat and oil shale | C4: Imports (PJ) | D4: 19 | E4: 12.416851 | F4: 15.0273 | G4: 15.048749 | L4: Advanced Economies | M4: PJ | N4: =D4183+D4195 -> 42225 | O4: =E4183+E4195 -> 43497.996 | P4: =F4183+F4195 -> 43389.806 | Q4: =G4183+G4195 -> 42740.591
A5: Australia | B5: Coal, peat and oil shale | C5: Exports (PJ) | D5: -10505 | E5: -9866.1883 | F5: -9687.7713 | G5: -9147.4906 | L5: Emerging Economies | M5: PJ | N5: =D5695+D5707 -> 70514 | O5: =E5695+E5707 -> 76740.932 | P5: =F5695+F5707 -> 79754.652 | Q5: =G5695+G5707 -> 83937.158
A6: Australia | B6: Coal, peat and oil shale | C6: Total energy supply (PJ) | D6: 1783 | E6: 1683.9936 | F6: 1567.0465 | G6: 1465.6333 | L6: Global | M6: PJ | N6: =D6559+D6571 -> 112739 | O6: =E6559+E6571 -> 120238.93 | P6: =F6559+F6571 -> 123144.46 | Q6: =G6559+G6571 -> 126677.75
A7: Australia | B7: Coal, peat and oil shale | C7: Electricity, CHP and heat plants (PJ) | D7: -1516 | E7: -1468.2661 | F7: -1395.8131 | G7: -1343.3934
A8: Australia | B8: Coal, peat and oil shale | C8: Oil refineries, transformation (PJ) | D8: 0 | E8: 0 | F8: 0 | G8: 0
A9: Australia | B9: Coal, peat and oil shale | C9: Total final consumption (PJ) | D9: 112 | E9: 113.33159 | F9: 113.07029 | G9: 106.45205
A10: Australia | B10: Coal, peat and oil shale | C10: Industry (PJ) | D10: 111 | E10: 113.09689 | F10: 112.92609 | G10: 106.30065
A11: Australia | B11: Coal, peat and oil shale | C11: Transport (PJ) | D11: 0 | E11: 0 | F11: 0 | G11: 0
A12: Australia | B12: Coal, peat and oil shale | C12: Residential (PJ) | D12: 0 | E12: 0.020997 | F12: 0 | G12: 0
A13: Australia | B13: Coal, peat and oil shale | C13: Commercial and public services (PJ) | D13: 1 | E13: 0.213698 | F13: 0.144198 | G13: 0.151399
A14: Australia | B14: Coal, peat and oil shale | C14: Other final consumption (PJ) | D14: 0 | E14: 0 | F14: 0 | G14: 0
A15: Australia | B15: Crude, NGL and feedstocks | C15: Production (PJ) | D15: 875 | E15: 785.06719 | F15: 806.79024 | G15: 747.02096
A16: Australia | B16: Crude, NGL and feedstocks | C16: Imports (PJ) | D16: 631 | E16: 491.78815 | F16: 359.45287 | G16: 337.5364
A17: Australia | B17: Crude, NGL and feedstocks | C17: Exports (PJ) | D17: -595 | E17: -563.59615 | F17: -592.66445 | G17: -575.49772
A18: Australia | B18: Crude, NGL and feedstocks | C18: Total energy supply (PJ) | D18: 911 | E18: 730.01859 | F18: 569.63567 | G18: 511.31896
... A86: Australia | B86: Electricity | C86: Other final consumption (PJ) | D86: 7 | E86: 7.461288 | F86: 6.351283 | G86: 7.292652
A87: Australia | B87: Heat | C87: Production (PJ) | D87: .. | E87: .. | F87: .. | G87: ..
A88: Australia | B88: Heat | C88: Imports (PJ) | D88: 0 | E88: 0 | F88: .. | G88: 0
A89: Australia | B89: Heat | C89: Exports (PJ) | D89: 0 | E89: 0 | F89: .. | G89: 0
A90: Australia | B90: Heat | C90: Total energy supply (PJ) | D90: .. | E90: .. | F90: .. | G90: ..
A91: Australia | B91: Heat | C91: Electricity, CHP and heat plants (PJ) | D91: .. | E91: .. | F91: .. | G91: ..
A92: Australia | B92: Heat | C92: Oil refineries, transformation (PJ) | D92: 0 | E92: 0 | F92: .. | G92: 0
A93: Australia | B93: Heat | C93: Total final consumption (PJ) | D93: .. | E93: .. | F93: .. | G93: ..
A94: Australia | B94: Heat | C94: Industry (PJ) | D94: .. | E94: .. | F94: .. | G94: ..
A95: Australia | B95: Heat | C95: Transport (PJ) | D95: .. | E95: .. | F95: .. | G95: ..
A96: Australia | B96: Heat | C96: Residential (PJ) | D96: .. | E96: .. | F96: .. | G96: ..
A97: Australia | B97: Heat | C97: Commercial and public services (PJ) | D97: .. | E97: .. | F97: .. | G97: ..
A98: Australia | B98: Heat | C98: Other final consumption (PJ) | D98: .. | E98: .. | F98: .. | G98: ..
A99: Australia | B99: Total | C99: Production (PJ) | D99: 18950 | E99: 17851.936 | F99: 18248.389 | G99: 17675.59
A100: Australia | B100: Total | C100: Imports (PJ) | D100: 2088 | E100: 1965.5544 | F100: 1999.669 | G100: 2139.4462
A101: Australia | B101: Total | C101: Exports (PJ) | D101: -15236 | E101: -14461.874 | F101: -14612.695 | G101: -13935.874
A102: Australia | B102: Total | C102: Total energy supply (PJ) | D102: 5540 | E102: 5383.9138 | F102: 5383.7554 | G102: 5500.2308
A103: Australia | B103: Total | C103: Electricity, CHP and heat plants (PJ) | D103: -1371 | E103: -1304.5265 | F103: -1251.7123 | G103: -1224.112
A104: Australia | B104: Total | C104: Oil refineries, transformation (PJ) | D104: -9 | E104: -17.863497 | F104: -1.46929 | G104: -4.291118
A105: Australia | B105: Total | C105: Total final consumption (PJ) | D105: 3306 | E105: 3314.0366 | F105: 3326.1235 | G105: 3415.9464
A106: Australia | B106: Total | C106: Industry (PJ) | D106: 941 | E106: 965.82272 | F106: 961.78107 | G106: 967.98951
A107: Australia | B107: Total | C107: Transport (PJ) | D107: 1292 | E107: 1248.6624 | F107: 1270.5218 | G107: 1377.1367
...
